Workbook

Sheet Home Worksheet
A1: Home Page for Nessus Report_20260210233823
A2: host_scan_data
A3: CVSS Score Total
A4: Medium
A5: low
A6: Information
A7: CPE Report Data
A8: Device Type
A9: HostConfigData
A10: UserAccountData
A11: Summary Report Data
A12: Vulnerability to IP Summary
... A17: Number of IP's Scanned
A18: Number of Discovered Systems | B18: 0
A20: Total Unique Critical Severity Vulnerability | B20: 0
A21: Total Unique High Severity Vulnerability | B21: 0
A22: Total Unique Medium Severity Vulnerability | B22: 1
A23: Total Unique Low Severity Vulnerability | B23: 3
A24: Total Unique Informational Severity Vulnerability | B24: 2
A26: Total Count of Critical Severity Vulnerability | B26: N/A
A27: Total Count of High Severity Vulnerability | B27: N/A
A28: Total Count of Medium Severity Vulnerability | B28: =SUM(medium!E3:E3) -> 0
A29: Total Count of Low Severity Vulnerability | B29: =SUM(low!E3:E5) -> 0
A31: The most common Critical Severity vulnerability
A32: The most common high Severity vulnerability
A33: Number of System with a critical(4) Severity Vulnerability | B33: =COUNTIF(HostConfigData!M3:M2,">0") -> 0
A34: Number of System with a High(3) Severity Vulnerability | B34: =COUNTIF(HostConfigData!L3:L2,">0") -> 0
A35: Number of System with a Medium(2) Severity Vulnerability | B35: =COUNTIF(HostConfigData!K3:K2,">0") -> 0
A36: Number of System with a Low(1) Severity Vulnerability | B36: =COUNTIF(HostConfigData!J3:J2,">0") -> 0
A37: Number of System with a Informational(NONE-0) Severity Vulnerability | B37: =COUNTIF(HostConfigData!I3:I2,">0") -> 0

Sheet host_scan_data
A1: 'Home Worksheet'!A1
A2: File | B2: IP Address | C2: FQDN | D2: Plugin ID | E2: Protocol | F2: Port | G2: Severity | H2: Plugin Family | I2: Plugin Name | J2: CVSS Vector | K2: CVSS Base Score | L2: CVSS Temporal Score | M2: Exploitability Ease | N2: Exploit Available | O2: Exploit Framework Canvas | P2: Exploit Framework Metasploit | Q2: Exploit Framework Core | R2: Metasploit Name | S2: Canvas Package | T2: Plugin Output
A3: .\scan.nessus | B3: host-001.example.local | C3: N/A | D3: 99999 | E3: tcp | F3: 0 | G3: 0 | H3: General | I3: Summary - Mock | J3: N/A | K3: N/A | L3: N/A | M3: N/A | N3: N/A | O3: N/A | P3: N/A | Q3: N/A | R3: N/A | S3: N/A
A4: .\scan.nessus | B4: host-001.example.local | C4: N/A | D4: 10001 | E4: tcp | F4: 0 | G4: 2 | H4: General | I4: Weak Password Policy Detected (mock) | J4: N/A | K4: N/A | L4: N/A | M4: N/A | N4: N/A | O4: N/A | P4: N/A | Q4: N/A | R4: N/A | S4: N/A
A5: .\scan.nessus | B5: host-001.example.local | C5: N/A | D5: 20002 | E5: tcp | F5: 0 | G5: 1 | H5: General | I5: Local User Accounts (mock report) | J5: N/A | K5: N/A | L5: N/A | M5: N/A | N5: N/A | O5: N/A | P5: N/A | Q5: N/A | R5: N/A | S5: N/A
A6: .\scan.nessus | B6: host-001.example.local | C6: N/A | D6: 30003 | E6: tcp | F6: 22 | G6: 1 | H6: General | I6: Open Port (mock) | J6: N/A | K6: N/A | L6: N/A | M6: N/A | N6: N/A | O6: N/A | P6: N/A | Q6: N/A | R6: N/A | S6: N/A
A7: .\scan.nessus | B7: host-002.example.local | C7: N/A | D7: 10002 | E7: tcp | F7: 0 | G7: 0 | H7: Configuration | I7: Policy Family - Configuration (mock) | J7: N/A | K7: N/A | L7: N/A | M7: N/A | N7: N/A | O7: N/A | P7: N/A | Q7: N/A | R7: N/A | S7: N/A
A8: .\scan.nessus | B8: host-002.example.local | C8: N/A | D8: 20003 | E8: tcp | F8: 0 | G8: 1 | H8: Configuration | I8: Local Users Found (mock) | J8: N/A | K8: N/A | L8: N/A | M8: N/A | N8: N/A | O8: N/A | P8: N/A | Q8: N/A | R8: N/A | S8: N/A

Sheet CVSS Score Total
A1: 'Home Worksheet'!A1
B2: Critical | C2: High | D2: Medium
A3: Multiplier | B3: 1 | C3: 1 | D3: 1
A5: Host IP Address | B5: Total | C5: Base Total | D5: Temporal Total | E5: Base Critical Severity (4) | F5: Temporal Critical Severity (4) | G5: Base High Severity (3) | H5: Temporal High Severity (3) | I5: Base Medium Severity (2) | J5: Temporal Medium Severity (2)

Sheet Medium
A1: 'Home Worksheet'!A1
A2: File | B2: plugin Family | C2: plugin id | D2: plugin Name | E2: count | F2: Bid | G2: CVE | H2: OSVDB | I2: CVSS Vector | J2: CVSS Base Score | K2: CVSS Temporal Score | L2: Solution | M2: Description | N2: Exploitability Ease | O2: Exploit Available | P2: Exploit Framework Canvas | Q2: Exploit Framework Metasploit | R2: Exploit Framework Core | S2: Metasploit Name | T2: Canvas Package | U2: Solution | V2: Synopsis | W2: plugin_publication_date | X2: plugin_modification_date | Y2: patch_publication_date | Z2: vuln_publication_date
A3: .\scan.nessus | B3: General | C3: 10001 | D3: Weak Password Policy Detected (mock) | E3: 1 | I3: N/A | J3: N/A | K3: N/A | L3: Review password policy and ensure minimum complexity is enforced. | M3: This mock finding represents a policy-family result (Authentication). | N3: N/A | O3: N/A | P3: N/A | Q3: N/A | R3: N/A | S3: N/A | T3: N/A | U3: Review password policy and ensure minimum complexity is enforced.

Sheet low
A1: 'Home Worksheet'!A1
A2: File | B2: plugin Family | C2: plugin id | D2: plugin Name | E2: count | F2: Bid | G2: CVE | H2: OSVDB | I2: CVSS Vector | J2: CVSS Base Score | K2: CVSS Temporal Score | L2: Solution | M2: Description | N2: Exploitability Ease | O2: Exploit Available | P2: Exploit Framework Canvas | Q2: Exploit Framework Metasploit | R2: Exploit Framework Core | S2: Metasploit Name | T2: Canvas Package | U2: Solution | V2: Synopsis | W2: plugin_publication_date | X2: plugin_modification_date | Y2: patch_publication_date | Z2: vuln_publication_date
A3: .\scan.nessus | B3: General | C3: 20002 | D3: Local User Accounts (mock report) | E3: 1 | I3: N/A | J3: N/A | K3: N/A | M3: Mock user account enumeration for testing user account reporting features. | N3: N/A | O3: N/A | P3: N/A | Q3: N/A | R3: N/A | S3: N/A | T3: N/A
A4: .\scan.nessus | B4: General | C4: 30003 | D4: Open Port (mock) | E4: 1 | I4: N/A | J4: N/A | K4: N/A | M4: Mock open service used to exercise port scanning and service reporting. | N4: N/A | O4: N/A | P4: N/A | Q4: N/A | R4: N/A | S4: N/A | T4: N/A
A5: .\scan.nessus | B5: Configuration | C5: 20003 | D5: Local Users Found (mock) | E5: 1 | I5: N/A | J5: N/A | K5: N/A | M5: Another mock user account entry for testing. | N5: N/A | O5: N/A | P5: N/A | Q5: N/A | R5: N/A | S5: N/A | T5: N/A

Sheet Information
A1: 'Home Worksheet'!A1
A2: File | B2: plugin Family | C2: plugin id | D2: plugin Name | E2: count | F2: Bid | G2: CVE | H2: OSVDB | I2: CVSS Vector | J2: CVSS Base Score | K2: CVSS Temporal Score | L2: Solution | M2: Description | N2: Exploitability Ease | O2: Exploit Available | P2: Exploit Framework Canvas | Q2: Exploit Framework Metasploit | R2: Exploit Framework Core | S2: Metasploit Name | T2: Canvas Package | U2: Solution | V2: Synopsis | W2: plugin_publication_date | X2: plugin_modification_date | Y2: patch_publication_date | Z2: vuln_publication_date
A3: .\scan.nessus | B3: General | C3: 99999 | D3: Summary - Mock | E3: 1 | I3: N/A | J3: N/A | K3: N/A | M3: Summary of the mock scan results (no sensitive data). | N3: N/A | O3: N/A | P3: N/A | Q3: N/A | R3: N/A | S3: N/A | T3: N/A
A4: .\scan.nessus | B4: Configuration | C4: 10002 | D4: Policy Family - Configuration (mock) | E4: 1 | I4: N/A | J4: N/A | K4: N/A | M4: A mock non-critical configuration check. | N4: N/A | O4: N/A | P4: N/A | Q4: N/A | R4: N/A | S4: N/A | T4: N/A

Sheet CPE Report Data
A1: 'Home Worksheet'!A1
A2: File | B2: IP Address | C2: FQDN | D2: Netbios Name | E2: Name | F2: Plugin Family | G2: Plugin ID | H2: Plugin Name | I2: CPE | J2: CPE Source

Sheet Device Type
A1: 'Home Worksheet'!A1
A2: File | B2: IP Address | C2: FQDN | D2: Netbios Name | E2: Name | F2: Device Type | G2: Confidence Level

Sheet HostConfigData
A1: 'Home Worksheet'!A1
A2: File | B2: IP Address | C2: FQDN | D2: Netbios Name | E2: OS | F2: Local Check Protocol | G2: MAC Address | H2: IP / Name | I2: Severity None (0) | J2: Severity Low (1) | K2: Severity Medium (2) | L2: Severity High (3) | M2: Severity Critical (4) | N2: Minimum password len | O2: Password history len | P2: Maximum password age days | Q2: Password must meet complexity requirements | R2: Minimum password age days | S2: Forced logoff time Seconds | T2: Locked account time seconds | U2: Time between failed logon seconds | V2: Number of invalid logon before locked out seconds
A3: .\scan.nessus | C3: N/A | E3: MockOS 1.0 | G3: 00:11:22:33:44:55 | H3: host-001.example.local | I3: 1 | J3: 2 | K3: 1 | L3: 0 | M3: 0
A4: .\scan.nessus | C4: N/A | E4: MockOS 2.0 | H4: host-002.example.local | I4: 1 | J4: 1 | K4: 0 | L4: 0 | M4: 0

Sheet UserAccountData
A1: 'Home Worksheet'!A1
A2: User Location | B2: Name | C2: SID | D2: type | E2: Never Changed Password | F2: Automatic Account Disabled | G2: Account Disabled | H2: Never Changed Password | I2: Never Logged In | J2: Guest Account Belongs to a Group | K2: Administrators | L2: Domain Administrators | M2: Account Operators | N2: Server Operators | O2: Backup Operators | P2: Print Operators | Q2: Replicator

Sheet Summary Report Data
A1: 'Home Worksheet'!A1
A2: User Account Sumamry
B3: User Type Count | C3: Never Changed Password | D3: Automatic Account Disabled | E3: Account Disabled | F3: Never Changed Password | G3: Never Logged In | H3: Guest Account Belongs to a Group | I3: Administrators | J3: Domain Administrators | K3: Account Operators | L3: Server Operators | M3: Backup Operators | N3: Print Operators | O3: Replicator
A4: Domain Administrator account | B4: =COUNTIF(UserAccountData!$D$3:$D$2,A4) -> 0 | C4: =SUMPRODUCT(--(UserAccountData!$D$3:$D$2 = A4)*--(UserAccountData!$E$3:$E$2 ="Y")) -> 0 | D4: =SUMPRODUCT(--(UserAccountData!$D$3:$D$2 = A4)*--(UserAccountData!$F$3:$F$2 ="Y")) -> 0 | E4: =SUMPRODUCT(--(UserAccountData!$D$3:$D$2 = A4)*--(UserAccountData!$G$3:$G$2 ="Y")) -> 0 | F4: =SUMPRODUCT(--(UserAccountData!$D$3:$D$2 = A4)*--(UserAccountData!$H$3:$H$2 ="Y")) -> 0 | G4: =SUMPRODUCT(--(UserAccountData!$D$3:$D$2 = A4)*--(UserAccountData!$I$3:$I$2 ="Y")) -> 0 | H4: =SUMPRODUCT(--(UserAccountData!$D$3:$D$2 = A4)*--(UserAccountData!$J$3:$J$2 ="Y")) -> 0 | I4: =SUMPRODUCT(--(UserAccountData!$D$3:$D$2 = A4)*--(UserAccountData!$K$3:$K$2 ="Y")) -> 0 | J4: =SUMPRODUCT(--(UserAccountData!$D$3:$D$2 = A4)*--(UserAccountData!$L$3:$L$2 ="Y")) -> 0 | K4: =SUMPRODUCT(--(UserAccountData!$D$3:$D$2 = A4)*--(UserAccountData!$M$3:$M$2 ="Y")) -> 0 | L4: =SUMPRODUCT(--(UserAccountData!$D$3:$D$2 = A4)*--(UserAccountData!$N$3:$N$2 ="Y")) -> 0 | M4: =SUMPRODUCT(--(UserAccountData!$D$3:$D$2 = A4)*--(UserAccountData!$O$3:$O$2 ="Y")) -> 0 | N4: =SUMPRODUCT(--(UserAccountData!$D$3:$D$2 = A4)*--(UserAccountData!$P$3:$P$2 ="Y")) -> 0 | O4: =SUMPRODUCT(--(UserAccountData!$D$3:$D$2 = A4)*--(UserAccountData!$Q$3:$Q$2 ="Y")) -> 0
A5: Domain Guest account | B5: =COUNTIF(UserAccountData!$D$3:$D$2,A5) -> 0 | C5: =SUMPRODUCT(--(UserAccountData!$D$3:$D$2 = A5),--(UserAccountData!$E$3:$E$2 ="Y")) -> 0 | D5: =SUMPRODUCT(--(UserAccountData!$D$3:$D$2 = A5),--(UserAccountData!$F$3:$F$2 ="Y")) -> 0 | E5: =SUMPRODUCT(--(UserAccountData!$D$3:$D$2 = A5),--(UserAccountData!$G$3:$G$2 ="Y")) -> 0 | F5: =SUMPRODUCT(--(UserAccountData!$D$3:$D$2 = A5),--(UserAccountData!$H$3:$H$2 ="Y")) -> 0 | G5: =SUMPRODUCT(--(UserAccountData!$D$3:$D$2 = A5),--(UserAccountData!$I$3:$I$2 ="Y")) -> 0 | H5: =SUMPRODUCT(--(UserAccountData!$D$3:$D$2 = A5),--(UserAccountData!$J$3:$J$2 ="Y")) -> 0 | I5: =SUMPRODUCT(--(UserAccountData!$D$3:$D$2 = A5),--(UserAccountData!$K$3:$K$2 ="Y")) -> 0 | J5: =SUMPRODUCT(--(UserAccountData!$D$3:$D$2 = A5),--(UserAccountData!$L$3:$L$2 ="Y")) -> 0 | K5: =SUMPRODUCT(--(UserAccountData!$D$3:$D$2 = A5),--(UserAccountData!$M$3:$M$2 ="Y")) -> 0 | L5: =SUMPRODUCT(--(UserAccountData!$D$3:$D$2 = A5),--(UserAccountData!$N$3:$N$2 ="Y")) -> 0 | M5: =SUMPRODUCT(--(UserAccountData!$D$3:$D$2 = A5),--(UserAccountData!$O$3:$O$2 ="Y")) -> 0 | N5: =SUMPRODUCT(--(UserAccountData!$D$3:$D$2 = A5),--(UserAccountData!$P$3:$P$2 ="Y")) -> 0 | O5: =SUMPRODUCT(--(UserAccountData!$D$3:$D$2 = A5),--(UserAccountData!$Q$3:$Q$2 ="Y")) -> 0
A6: Domain User | B6: =COUNTIF(UserAccountData!$D$3:$D$2,A6) -> 0 | C6: =SUMPRODUCT(--(UserAccountData!$D$3:$D$2 = A6),--(UserAccountData!$E$3:$E$2 ="Y")) -> 0 | D6: =SUMPRODUCT(--(UserAccountData!$D$3:$D$2 = A6),--(UserAccountData!$F$3:$F$2 ="Y")) -> 0 | E6: =SUMPRODUCT(--(UserAccountData!$D$3:$D$2 = A6),--(UserAccountData!$G$3:$G$2 ="Y")) -> 0 | F6: =SUMPRODUCT(--(UserAccountData!$D$3:$D$2 = A6),--(UserAccountData!$H$3:$H$2 ="Y")) -> 0 | G6: =SUMPRODUCT(--(UserAccountData!$D$3:$D$2 = A6),--(UserAccountData!$I$3:$I$2 ="Y")) -> 0 | H6: =SUMPRODUCT(--(UserAccountData!$D$3:$D$2 = A6),--(UserAccountData!$J$3:$J$2 ="Y")) -> 0 | I6: =SUMPRODUCT(--(UserAccountData!$D$3:$D$2 = A6),--(UserAccountData!$K$3:$K$2 ="Y")) -> 0 | J6: =SUMPRODUCT(--(UserAccountData!$D$3:$D$2 = A6),--(UserAccountData!$L$3:$L$2 ="Y")) -> 0 | K6: =SUMPRODUCT(--(UserAccountData!$D$3:$D$2 = A6),--(UserAccountData!$M$3:$M$2 ="Y")) -> 0 | L6: =SUMPRODUCT(--(UserAccountData!$D$3:$D$2 = A6),--(UserAccountData!$N$3:$N$2 ="Y")) -> 0 | M6: =SUMPRODUCT(--(UserAccountData!$D$3:$D$2 = A6),--(UserAccountData!$O$3:$O$2 ="Y")) -> 0 | N6: =SUMPRODUCT(--(UserAccountData!$D$3:$D$2 = A6),--(UserAccountData!$P$3:$P$2 ="Y")) -> 0 | O6: =SUMPRODUCT(--(UserAccountData!$D$3:$D$2 = A6),--(UserAccountData!$Q$3:$Q$2 ="Y")) -> 0
A7: Administrator account | B7: =COUNTIF(UserAccountData!$D$3:$D$2,A7) -> 0 | C7: =SUMPRODUCT(--(UserAccountData!$D$3:$D$2 = A7),--(UserAccountData!$E$3:$E$2 ="Y")) -> 0 | D7: =SUMPRODUCT(--(UserAccountData!$D$3:$D$2 = A7),--(UserAccountData!$F$3:$F$2 ="Y")) -> 0 | E7: =SUMPRODUCT(--(UserAccountData!$D$3:$D$2 = A7),--(UserAccountData!$G$3:$G$2 ="Y")) -> 0 | F7: =SUMPRODUCT(--(UserAccountData!$D$3:$D$2 = A7),--(UserAccountData!$H$3:$H$2 ="Y")) -> 0 | G7: =SUMPRODUCT(--(UserAccountData!$D$3:$D$2 = A7),--(UserAccountData!$I$3:$I$2 ="Y")) -> 0 | H7: =SUMPRODUCT(--(UserAccountData!$D$3:$D$2 = A7),--(UserAccountData!$J$3:$J$2 ="Y")) -> 0 | I7: =SUMPRODUCT(--(UserAccountData!$D$3:$D$2 = A7),--(UserAccountData!$K$3:$K$2 ="Y")) -> 0 | J7: =SUMPRODUCT(--(UserAccountData!$D$3:$D$2 = A7),--(UserAccountData!$L$3:$L$2 ="Y")) -> 0 | K7: =SUMPRODUCT(--(UserAccountData!$D$3:$D$2 = A7),--(UserAccountData!$M$3:$M$2 ="Y")) -> 0 | L7: =SUMPRODUCT(--(UserAccountData!$D$3:$D$2 = A7),--(UserAccountData!$N$3:$N$2 ="Y")) -> 0 | M7: =SUMPRODUCT(--(UserAccountData!$D$3:$D$2 = A7),--(UserAccountData!$O$3:$O$2 ="Y")) -> 0 | N7: =SUMPRODUCT(--(UserAccountData!$D$3:$D$2 = A7),--(UserAccountData!$P$3:$P$2 ="Y")) -> 0 | O7: =SUMPRODUCT(--(UserAccountData!$D$3:$D$2 = A7),--(UserAccountData!$Q$3:$Q$2 ="Y")) -> 0
A8: Guest account | B8: =COUNTIF(UserAccountData!$D$3:$D$2,A8) -> 0 | C8: =SUMPRODUCT(--(UserAccountData!$D$3:$D$2 = A8),--(UserAccountData!$E$3:$E$2 ="Y")) -> 0 | D8: =SUMPRODUCT(--(UserAccountData!$D$3:$D$2 = A8),--(UserAccountData!$F$3:$F$2 ="Y")) -> 0 | E8: =SUMPRODUCT(--(UserAccountData!$D$3:$D$2 = A8),--(UserAccountData!$G$3:$G$2 ="Y")) -> 0 | F8: =SUMPRODUCT(--(UserAccountData!$D$3:$D$2 = A8),--(UserAccountData!$H$3:$H$2 ="Y")) -> 0 | G8: =SUMPRODUCT(--(UserAccountData!$D$3:$D$2 = A8),--(UserAccountData!$I$3:$I$2 ="Y")) -> 0 | H8: =SUMPRODUCT(--(UserAccountData!$D$3:$D$2 = A8),--(UserAccountData!$J$3:$J$2 ="Y")) -> 0 | I8: =SUMPRODUCT(--(UserAccountData!$D$3:$D$2 = A8),--(UserAccountData!$K$3:$K$2 ="Y")) -> 0 | J8: =SUMPRODUCT(--(UserAccountData!$D$3:$D$2 = A8),--(UserAccountData!$L$3:$L$2 ="Y")) -> 0 | K8: =SUMPRODUCT(--(UserAccountData!$D$3:$D$2 = A8),--(UserAccountData!$M$3:$M$2 ="Y")) -> 0 | L8: =SUMPRODUCT(--(UserAccountData!$D$3:$D$2 = A8),--(UserAccountData!$N$3:$N$2 ="Y")) -> 0 | M8: =SUMPRODUCT(--(UserAccountData!$D$3:$D$2 = A8),--(UserAccountData!$O$3:$O$2 ="Y")) -> 0 | N8: =SUMPRODUCT(--(UserAccountData!$D$3:$D$2 = A8),--(UserAccountData!$P$3:$P$2 ="Y")) -> 0 | O8: =SUMPRODUCT(--(UserAccountData!$D$3:$D$2 = A8),--(UserAccountData!$Q$3:$Q$2 ="Y")) -> 0
A9: Local User | B9: =COUNTIF(UserAccountData!$D$3:$D$2,A9) -> 0 | C9: =SUMPRODUCT(--(UserAccountData!$D$3:$D$2 = A9),--(UserAccountData!$E$3:$E$2 ="Y")) -> 0 | D9: =SUMPRODUCT(--(UserAccountData!$D$3:$D$2 = A9),--(UserAccountData!$F$3:$F$2 ="Y")) -> 0 | E9: =SUMPRODUCT(--(UserAccountData!$D$3:$D$2 = A9),--(UserAccountData!$G$3:$G$2 ="Y")) -> 0 | F9: =SUMPRODUCT(--(UserAccountData!$D$3:$D$2 = A9),--(UserAccountData!$H$3:$H$2 ="Y")) -> 0 | G9: =SUMPRODUCT(--(UserAccountData!$D$3:$D$2 = A9),--(UserAccountData!$I$3:$I$2 ="Y")) -> 0 | H9: =SUMPRODUCT(--(UserAccountData!$D$3:$D$2 = A9),--(UserAccountData!$J$3:$J$2 ="Y")) -> 0 | I9: =SUMPRODUCT(--(UserAccountData!$D$3:$D$2 = A9),--(UserAccountData!$K$3:$K$2 ="Y")) -> 0 | J9: =SUMPRODUCT(--(UserAccountData!$D$3:$D$2 = A9),--(UserAccountData!$L$3:$L$2 ="Y")) -> 0 | K9: =SUMPRODUCT(--(UserAccountData!$D$3:$D$2 = A9),--(UserAccountData!$M$3:$M$2 ="Y")) -> 0 | L9: =SUMPRODUCT(--(UserAccountData!$D$3:$D$2 = A9),--(UserAccountData!$N$3:$N$2 ="Y")) -> 0 | M9: =SUMPRODUCT(--(UserAccountData!$D$3:$D$2 = A9),--(UserAccountData!$O$3:$O$2 ="Y")) -> 0 | N9: =SUMPRODUCT(--(UserAccountData!$D$3:$D$2 = A9),--(UserAccountData!$P$3:$P$2 ="Y")) -> 0 | O9: =SUMPRODUCT(--(UserAccountData!$D$3:$D$2 = A9),--(UserAccountData!$Q$3:$Q$2 ="Y")) -> 0
A10: Unknown | B10: =COUNTIF(UserAccountData!$D$3:$D$2,A10) -> 0 | C10: =SUMPRODUCT(--(UserAccountData!$D$3:$D$2 = A10),--(UserAccountData!$E$3:$E$2 ="Y")) -> 0 | D10: =SUMPRODUCT(--(UserAccountData!$D$3:$D$2 = A10),--(UserAccountData!$F$3:$F$2 ="Y")) -> 0 | E10: =SUMPRODUCT(--(UserAccountData!$D$3:$D$2 = A10),--(UserAccountData!$G$3:$G$2 ="Y")) -> 0 | F10: =SUMPRODUCT(--(UserAccountData!$D$3:$D$2 = A10),--(UserAccountData!$H$3:$H$2 ="Y")) -> 0 | G10: =SUMPRODUCT(--(UserAccountData!$D$3:$D$2 = A10),--(UserAccountData!$I$3:$I$2 ="Y")) -> 0 | H10: =SUMPRODUCT(--(UserAccountData!$D$3:$D$2 = A10),--(UserAccountData!$J$3:$J$2 ="Y")) -> 0 | I10: =SUMPRODUCT(--(UserAccountData!$D$3:$D$2 = A10),--(UserAccountData!$K$3:$K$2 ="Y")) -> 0 | J10: =SUMPRODUCT(--(UserAccountData!$D$3:$D$2 = A10),--(UserAccountData!$L$3:$L$2 ="Y")) -> 0 | K10: =SUMPRODUCT(--(UserAccountData!$D$3:$D$2 = A10),--(UserAccountData!$M$3:$M$2 ="Y")) -> 0 | L10: =SUMPRODUCT(--(UserAccountData!$D$3:$D$2 = A10),--(UserAccountData!$N$3:$N$2 ="Y")) -> 0 | M10: =SUMPRODUCT(--(UserAccountData!$D$3:$D$2 = A10),--(UserAccountData!$O$3:$O$2 ="Y")) -> 0 | N10: =SUMPRODUCT(--(UserAccountData!$D$3:$D$2 = A10),--(UserAccountData!$P$3:$P$2 ="Y")) -> 0 | O10: =SUMPRODUCT(--(UserAccountData!$D$3:$D$2 = A10),--(UserAccountData!$Q$3:$Q$2 ="Y")) -> 0
A11: User | B11: =COUNTIF(UserAccountData!$D$3:$D$2,A11) -> 0 | C11: =SUMPRODUCT(--(UserAccountData!$D$3:$D$2 = A11),--(UserAccountData!$E$3:$E$2 ="Y")) -> 0 | D11: =SUMPRODUCT(--(UserAccountData!$D$3:$D$2 = A11),--(UserAccountData!$F$3:$F$2 ="Y")) -> 0 | E11: =SUMPRODUCT(--(UserAccountData!$D$3:$D$2 = A11),--(UserAccountData!$G$3:$G$2 ="Y")) -> 0 | F11: =SUMPRODUCT(--(UserAccountData!$D$3:$D$2 = A11),--(UserAccountData!$H$3:$H$2 ="Y")) -> 0 | G11: =SUMPRODUCT(--(UserAccountData!$D$3:$D$2 = A11),--(UserAccountData!$I$3:$I$2 ="Y")) -> 0 | H11: =SUMPRODUCT(--(UserAccountData!$D$3:$D$2 = A11),--(UserAccountData!$J$3:$J$2 ="Y")) -> 0 | I11: =SUMPRODUCT(--(UserAccountData!$D$3:$D$2 = A11),--(UserAccountData!$K$3:$K$2 ="Y")) -> 0 | J11: =SUMPRODUCT(--(UserAccountData!$D$3:$D$2 = A11),--(UserAccountData!$L$3:$L$2 ="Y")) -> 0 | K11: =SUMPRODUCT(--(UserAccountData!$D$3:$D$2 = A11),--(UserAccountData!$M$3:$M$2 ="Y")) -> 0 | L11: =SUMPRODUCT(--(UserAccountData!$D$3:$D$2 = A11),--(UserAccountData!$N$3:$N$2 ="Y")) -> 0 | M11: =SUMPRODUCT(--(UserAccountData!$D$3:$D$2 = A11),--(UserAccountData!$O$3:$O$2 ="Y")) -> 0 | N11: =SUMPRODUCT(--(UserAccountData!$D$3:$D$2 = A11),--(UserAccountData!$P$3:$P$2 ="Y")) -> 0 | O11: =SUMPRODUCT(--(UserAccountData!$D$3:$D$2 = A11),--(UserAccountData!$Q$3:$Q$2 ="Y")) -> 0
A12: Group | B12: =COUNTIF(UserAccountData!$D$3:$D$2,A12) -> 0 | C12: =SUMPRODUCT(--(UserAccountData!$D$3:$D$2 = A12),--(UserAccountData!$E$3:$E$2 ="Y")) -> 0 | D12: =SUMPRODUCT(--(UserAccountData!$D$3:$D$2 = A12),--(UserAccountData!$F$3:$F$2 ="Y")) -> 0 | E12: =SUMPRODUCT(--(UserAccountData!$D$3:$D$2 = A12),--(UserAccountData!$G$3:$G$2 ="Y")) -> 0 | F12: =SUMPRODUCT(--(UserAccountData!$D$3:$D$2 = A12),--(UserAccountData!$H$3:$H$2 ="Y")) -> 0 | G12: =SUMPRODUCT(--(UserAccountData!$D$3:$D$2 = A12),--(UserAccountData!$I$3:$I$2 ="Y")) -> 0 | H12: =SUMPRODUCT(--(UserAccountData!$D$3:$D$2 = A12),--(UserAccountData!$J$3:$J$2 ="Y")) -> 0 | I12: =SUMPRODUCT(--(UserAccountData!$D$3:$D$2 = A12),--(UserAccountData!$K$3:$K$2 ="Y")) -> 0 | J12: =SUMPRODUCT(--(UserAccountData!$D$3:$D$2 = A12),--(UserAccountData!$L$3:$L$2 ="Y")) -> 0 | K12: =SUMPRODUCT(--(UserAccountData!$D$3:$D$2 = A12),--(UserAccountData!$M$3:$M$2 ="Y")) -> 0 | L12: =SUMPRODUCT(--(UserAccountData!$D$3:$D$2 = A12),--(UserAccountData!$N$3:$N$2 ="Y")) -> 0 | M12: =SUMPRODUCT(--(UserAccountData!$D$3:$D$2 = A12),--(UserAccountData!$O$3:$O$2 ="Y")) -> 0 | N12: =SUMPRODUCT(--(UserAccountData!$D$3:$D$2 = A12),--(UserAccountData!$P$3:$P$2 ="Y")) -> 0 | O12: =SUMPRODUCT(--(UserAccountData!$D$3:$D$2 = A12),--(UserAccountData!$Q$3:$Q$2 ="Y")) -> 0
A13: Computer Account | B13: =COUNTIF(UserAccountData!$D$3:$D$2,A13) -> 0 | C13: =SUMPRODUCT(--(UserAccountData!$D$3:$D$2 = A13),--(UserAccountData!$E$3:$E$2 ="Y")) -> 0 | D13: =SUMPRODUCT(--(UserAccountData!$D$3:$D$2 = A13),--(UserAccountData!$F$3:$F$2 ="Y")) -> 0 | E13: =SUMPRODUCT(--(UserAccountData!$D$3:$D$2 = A13),--(UserAccountData!$G$3:$G$2 ="Y")) -> 0 | F13: =SUMPRODUCT(--(UserAccountData!$D$3:$D$2 = A13),--(UserAccountData!$H$3:$H$2 ="Y")) -> 0 | G13: =SUMPRODUCT(--(UserAccountData!$D$3:$D$2 = A13),--(UserAccountData!$I$3:$I$2 ="Y")) -> 0 | H13: =SUMPRODUCT(--(UserAccountData!$D$3:$D$2 = A13),--(UserAccountData!$J$3:$J$2 ="Y")) -> 0 | I13: =SUMPRODUCT(--(UserAccountData!$D$3:$D$2 = A13),--(UserAccountData!$K$3:$K$2 ="Y")) -> 0 | J13: =SUMPRODUCT(--(UserAccountData!$D$3:$D$2 = A13),--(UserAccountData!$L$3:$L$2 ="Y")) -> 0 | K13: =SUMPRODUCT(--(UserAccountData!$D$3:$D$2 = A13),--(UserAccountData!$M$3:$M$2 ="Y")) -> 0 | L13: =SUMPRODUCT(--(UserAccountData!$D$3:$D$2 = A13),--(UserAccountData!$N$3:$N$2 ="Y")) -> 0 | M13: =SUMPRODUCT(--(UserAccountData!$D$3:$D$2 = A13),--(UserAccountData!$O$3:$O$2 ="Y")) -> 0 | N13: =SUMPRODUCT(--(UserAccountData!$D$3:$D$2 = A13),--(UserAccountData!$P$3:$P$2 ="Y")) -> 0 | O13: =SUMPRODUCT(--(UserAccountData!$D$3:$D$2 = A13),--(UserAccountData!$Q$3:$Q$2 ="Y")) -> 0
A17: Critical Severity Vulnerability Top 10 By Plugin Family
A18: plugin Family | B18: plugin id | C18: plugin Name | D18: count
A22: High Severity Vulnerability Top 10 By Plugin Family
A23: plugin Family | B23: plugin id | C23: plugin Name | D23: count
A27: Medium Severity Vulnerability Top 10 By Plugin Family
A28: plugin Family | B28: plugin id | C28: plugin Name | D28: count
A29: General | B29: 10001 | C29: Weak Password Policy Detected (mock) | D29: 1

Sheet Vulnerability to IP Summary
A1: 'Home Worksheet'!A1
A2: File | B2: Severity | C2: Plugin ID | D2: Plugin Name | E2: IP Count | F2: IP Addresses
A3: .\scan.nessus | B3: Low (1) | C3: 30003 | D3: Open Port (mock) | E3: 1 | F3: host-001.example.local
A4: .\scan.nessus | B4: Low (1) | C4: 20002 | D4: Local User Accounts (mock report) | E4: 1 | F4: host-001.example.local
A5: .\scan.nessus | B5: Low (1) | C5: 20003 | D5: Local Users Found (mock) | E5: 1 | F5: host-002.example.local
A6: .\scan.nessus | B6: Informational (0) | C6: 99999 | D6: Summary - Mock | E6: 1 | F6: host-001.example.local
A7: .\scan.nessus | B7: Informational (0) | C7: 10002 | D7: Policy Family - Configuration (mock) | E7: 1 | F7: host-002.example.local
A8: .\scan.nessus | B8: Medium (2) | C8: 10001 | D8: Weak Password Policy Detected (mock) | E8: 1 | F8: host-001.example.local

Sheet HostSummary Report Data
A1: 'Home Worksheet'!A1
A2: Host Summary Table operating-system
A3: operating-system Values | B3: Count
A4: MockOS 2.0 | B4: 1
A5: MockOS 1.0 | B5: 1
A16: Host Summary Table local-checks-proto
A17: local-checks-proto Values | B17: Count
A18: Unknown | B18: 2
A29: Host Summary Table name
A30: name Values | B30: Count
A31: host-002.example.local | B31: 1
A32: host-001.example.local | B32: 1
A43: Host Summary Table sev0
A44: The number of Hosts with sev0 discovered | B44: Count
A45: 1 | B45: 2
A56: Host Summary Table sev1
A57: The number of Hosts with sev1 discovered | B57: Count
A58: 2 | B58: 1
A59: 1 | B59: 1
A70: Host Summary Table sev2
A71: The number of Hosts with sev2 discovered | B71: Count
A72: 1 | B72: 1
A73: 0 | B73: 1
A84: Host Summary Table sev3
A85: The number of Hosts with sev3 discovered | B85: Count
A86: 0 | B86: 2
A97: Host Summary Table sev4
A98: The number of Hosts with sev4 discovered | B98: Count
A99: 0 | B99: 2
A110: Host Summary Table Minimum password len
A111: Minimum password len Values | B111: Count
A112: Unknown | B112: 2
A123: Host Summary Table Password history len
A124: Password history len Values | B124: Count
A125: Unknown | B125: 2
A136: Host Summary Table Maximum password age (d)
A137: Maximum password age (d) Values | B137: Count
A138: Unknown | B138: 2
A149: Host Summary Table Password must meet complexity requirements
A150: Password must meet complexity requirements Values | B150: Count
...
